Workbook

Sheet заявки всего
B1: Заявки всего
G3: 46235
A4: Шифр | B4: Станция погрузки | C4: Дорога погрузки | D4: Клиент | E4: Дивизион | F4: Всего | G4: =G3 -> 46235 | H4: =G3+1 -> 46236 | I4: =G3+2 -> 46237 | J4: =G3+3 -> 46238 | K4: =G3+4 -> 46239 | L4: =G3+5 -> 46240 | M4: =G3+6 -> 46241 | N4: =G3+7 -> 46242 | O4: =G3+8 -> 46243 | P4: =G3+9 -> 46244 | Q4: =G3+10 -> 46245 | R4: =G3+11 -> 46246 | S4: =G3+12 -> 46247 | T4: =G3+13 -> 46248 | U4: =G3+14 -> 46249 | V4: =G3+15 -> 46250 | W4: =G3+16 -> 46251 | X4: =G3+17 -> 46252 | Y4: =G3+18 -> 46253 | Z4: =G3+19 -> 46254 | AA4: =G3+20 -> 46255 | AB4: =G3+21 -> 46256 | AC4: =G3+22 -> 46257 | AD4: =G3+23 -> 46258 | AE4: =G3+24 -> 46259 | AF4: =G3+25 -> 46260 | AG4: =G3+26 -> 46261 | AH4: =G3+27 -> 46262 | AI4: =G3+28 -> 46263 | AJ4: =G3+29 -> 46264 | AK4: =G3+30 -> 46265
E5: Всего | F5: =AVERAGE(G5:AK5) -> 0 | G5: =SUM(G10:G500) -> 0 | H5: =SUM(H10:H500) -> 0 | I5: =SUM(I10:I500) -> 0 | J5: =SUM(J10:J500) -> 0 | K5: =SUM(K10:K500) -> 0 | L5: =SUM(L10:L500) -> 0 | M5: =SUM(M10:M500) -> 0 | N5: =SUM(N10:N500) -> 0 | ... AK5: =SUM(AK10:AK500) -> 0
E6: Северо-запад | F6: =AVERAGE(H6:AK6) -> 0 | G6: =SUMIF($E$10:$E$500,$E$6,G10:G500) -> 0 | H6: =SUMIF($E$10:$E$500,$E$6,H10:H500) -> 0 | I6: =SUMIF($E$10:$E$500,$E$6,I10:I500) -> 0 | J6: =SUMIF($E$10:$E$500,$E$6,J10:J500) -> 0 | K6: =SUMIF($E$10:$E$500,$E$6,K10:K500) -> 0 | L6: =SUMIF($E$10:$E$500,$E$6,L10:L500) -> 0 | M6: =SUMIF($E$10:$E$500,$E$6,M10:M500) -> 0 | N6: =SUMIF($E$10:$E$500,$E$6,N10:N500) -> 0 | ... AK6: =SUMIF($E$10:$E$500,$E$6,AK10:AK500) -> 0
E7: Восток | F7: =AVERAGE(H7:AK7) -> 0 | G7: =SUMIF($E$10:$E$500,$E$7,G10:G500) -> 0 | H7: =SUMIF($E$10:$E$500,$E$7,H10:H500) -> 0 | I7: =SUMIF($E$10:$E$500,$E$7,I10:I500) -> 0 | J7: =SUMIF($E$10:$E$500,$E$7,J10:J500) -> 0 | K7: =SUMIF($E$10:$E$500,$E$7,K10:K500) -> 0 | L7: =SUMIF($E$10:$E$500,$E$7,L10:L500) -> 0 | M7: =SUMIF($E$10:$E$500,$E$7,M10:M500) -> 0 | N7: =SUMIF($E$10:$E$500,$E$7,N10:N500) -> 0 | ... AK7: =SUMIF($E$10:$E$500,$E$7,AK10:AK500) -> 0
E8: Центр | F8: =AVERAGE(H8:AK8) -> 0 | G8: =SUMIF($E$10:$E$500,$E$8,G10:G500) -> 0 | H8: =SUMIF($E$10:$E$500,$E$8,H10:H500) -> 0 | I8: =SUMIF($E$10:$E$500,$E$8,I10:I500) -> 0 | J8: =SUMIF($E$10:$E$500,$E$8,J10:J500) -> 0 | K8: =SUMIF($E$10:$E$500,$E$8,K10:K500) -> 0 | L8: =SUMIF($E$10:$E$500,$E$8,L10:L500) -> 0 | M8: =SUMIF($E$10:$E$500,$E$8,M10:M500) -> 0 | N8: =SUMIF($E$10:$E$500,$E$8,N10:N500) -> 0 | ... AK8: =SUMIF($E$10:$E$500,$E$8,AK10:AK500) -> 0
E9: Юг | F9: =AVERAGE(H9:AK9) -> 0 | G9: =SUMIF($E$10:$E$500,$E$9,G10:G500) -> 0 | H9: =SUMIF($E$10:$E$500,$E$9,H10:H500) -> 0 | I9: =SUMIF($E$10:$E$500,$E$9,I10:I500) -> 0 | J9: =SUMIF($E$10:$E$500,$E$9,J10:J500) -> 0 | K9: =SUMIF($E$10:$E$500,$E$9,K10:K500) -> 0 | L9: =SUMIF($E$10:$E$500,$E$9,L10:L500) -> 0 | M9: =SUMIF($E$10:$E$500,$E$9,M10:M500) -> 0 | N9: =SUMIF($E$10:$E$500,$E$9,N10:N500) -> 0 | ... AK9: =SUMIF($E$10:$E$500,$E$9,AK10:AK500) -> 0

Sheet заявка на день
B1: Заявки на день
G3: 46235
A4: Шифр | B4: Станция погрузки | C4: Дорога погрузки | D4: Клиент | E4: Дивизион | F4: Всего | G4: =G3 -> 46235 | H4: =G3+1 -> 46236 | I4: =G3+2 -> 46237 | J4: =G3+3 -> 46238 | K4: =G3+4 -> 46239 | L4: =G3+5 -> 46240 | M4: =G3+6 -> 46241 | N4: =G3+7 -> 46242 | O4: =G3+8 -> 46243 | P4: =G3+9 -> 46244 | Q4: =G3+10 -> 46245 | R4: =G3+11 -> 46246 | S4: =G3+12 -> 46247 | T4: =G3+13 -> 46248 | U4: =G3+14 -> 46249 | V4: =G3+15 -> 46250 | W4: =G3+16 -> 46251 | X4: =G3+17 -> 46252 | Y4: =G3+18 -> 46253 | Z4: =G3+19 -> 46254 | AA4: =G3+20 -> 46255 | AB4: =G3+21 -> 46256 | AC4: =G3+22 -> 46257 | AD4: =G3+23 -> 46258 | AE4: =G3+24 -> 46259 | AF4: =G3+25 -> 46260 | AG4: =G3+26 -> 46261 | AH4: =G3+27 -> 46262 | AI4: =G3+28 -> 46263 | AJ4: =G3+29 -> 46264 | AK4: =G3+30 -> 46265
E5: Всего | F5: =AVERAGE(G5:AK5) -> 0 | G5: =SUM(G10:G5503) -> 0 | H5: =SUM(H10:H5503) -> 0 | I5: =SUM(I10:I5503) -> 0 | J5: =SUM(J10:J5503) -> 0 | K5: =SUM(K10:K5503) -> 0 | L5: =SUM(L10:L5503) -> 0 | M5: =SUM(M10:M5503) -> 0 | N5: =SUM(N10:N5503) -> 0 | ... AK5: =SUM(AK10:AK5503) -> 0
E6: Северо-запад | F6: =AVERAGE(H6:AK6) -> 0 | G6: =SUMIF($E$10:$E$5503,$E$6,G10:G5503) -> 0 | H6: =SUMIF($E$10:$E$5503,$E$6,H10:H5503) -> 0 | I6: =SUMIF($E$10:$E$5503,$E$6,I10:I5503) -> 0 | J6: =SUMIF($E$10:$E$5503,$E$6,J10:J5503) -> 0 | K6: =SUMIF($E$10:$E$5503,$E$6,K10:K5503) -> 0 | L6: =SUMIF($E$10:$E$5503,$E$6,L10:L5503) -> 0 | M6: =SUMIF($E$10:$E$5503,$E$6,M10:M5503) -> 0 | N6: =SUMIF($E$10:$E$5503,$E$6,N10:N5503) -> 0 | ... AK6: =SUMIF($E$10:$E$5503,$E$6,AK10:AK5503) -> 0
E7: Восток | F7: =AVERAGE(H7:AK7) -> 0 | G7: =SUMIF($E$10:$E$5503,$E$7,G10:G5503) -> 0 | H7: =SUMIF($E$10:$E$5503,$E$7,H10:H5503) -> 0 | I7: =SUMIF($E$10:$E$5503,$E$7,I10:I5503) -> 0 | J7: =SUMIF($E$10:$E$5503,$E$7,J10:J5503) -> 0 | K7: =SUMIF($E$10:$E$5503,$E$7,K10:K5503) -> 0 | L7: =SUMIF($E$10:$E$5503,$E$7,L10:L5503) -> 0 | M7: =SUMIF($E$10:$E$5503,$E$7,M10:M5503) -> 0 | N7: =SUMIF($E$10:$E$5503,$E$7,N10:N5503) -> 0 | ... AK7: =SUMIF($E$10:$E$5503,$E$7,AK10:AK5503) -> 0
E8: Центр | F8: =AVERAGE(H8:AK8) -> 0 | G8: =SUMIF($E$10:$E$5503,$E$8,G10:G5503) -> 0 | H8: =SUMIF($E$10:$E$5503,$E$8,H10:H5503) -> 0 | I8: =SUMIF($E$10:$E$5503,$E$8,I10:I5503) -> 0 | J8: =SUMIF($E$10:$E$5503,$E$8,J10:J5503) -> 0 | K8: =SUMIF($E$10:$E$5503,$E$8,K10:K5503) -> 0 | L8: =SUMIF($E$10:$E$5503,$E$8,L10:L5503) -> 0 | M8: =SUMIF($E$10:$E$5503,$E$8,M10:M5503) -> 0 | N8: =SUMIF($E$10:$E$5503,$E$8,N10:N5503) -> 0 | ... AK8: =SUMIF($E$10:$E$5503,$E$8,AK10:AK5503) -> 0
E9: Юг | F9: =AVERAGE(H9:AK9) -> 0 | G9: =SUMIF($E$10:$E$5503,$E$9,G10:G5503) -> 0 | H9: =SUMIF($E$10:$E$5503,$E$9,H10:H5503) -> 0 | I9: =SUMIF($E$10:$E$5503,$E$9,I10:I5503) -> 0 | J9: =SUMIF($E$10:$E$5503,$E$9,J10:J5503) -> 0 | K9: =SUMIF($E$10:$E$5503,$E$9,K10:K5503) -> 0 | L9: =SUMIF($E$10:$E$5503,$E$9,L10:L5503) -> 0 | M9: =SUMIF($E$10:$E$5503,$E$9,M10:M5503) -> 0 | N9: =SUMIF($E$10:$E$5503,$E$9,N10:N5503) -> 0 | ... AK9: =SUMIF($E$10:$E$5503,$E$9,AK10:AK5503) -> 0

Sheet погружено всего
B1: Погружено всего
G3: 46235
A4: Шифр | B4: Станция погрузки | C4: Дорога погрузки | D4: Клиент | E4: Дивизион | F4: План | G4: =G3 -> 46235 | H4: =G3+1 -> 46236 | I4: =G3+2 -> 46237 | J4: =G3+3 -> 46238 | K4: =G3+4 -> 46239 | L4: =G3+5 -> 46240 | M4: =G3+6 -> 46241 | N4: =G3+7 -> 46242 | O4: =G3+8 -> 46243 | P4: =G3+9 -> 46244 | Q4: =G3+10 -> 46245 | R4: =G3+11 -> 46246 | S4: =G3+12 -> 46247 | T4: =G3+13 -> 46248 | U4: =G3+14 -> 46249 | V4: =G3+15 -> 46250 | W4: =G3+16 -> 46251 | X4: =G3+17 -> 46252 | Y4: =G3+18 -> 46253 | Z4: =G3+19 -> 46254 | AA4: =G3+20 -> 46255 | AB4: =G3+21 -> 46256 | AC4: =G3+22 -> 46257 | AD4: =G3+23 -> 46258 | AE4: =G3+24 -> 46259 | AF4: =G3+25 -> 46260 | AG4: =G3+26 -> 46261 | AH4: =G3+27 -> 46262 | AI4: =G3+28 -> 46263 | AJ4: =G3+29 -> 46264 | AK4: =G3+30 -> 46265
E5: Всего | F5: ='заявки всего'!G5 -> 0 | G5: =SUM(G10:G5503) -> 0 | H5: =SUM(H10:H5503) -> 0 | I5: =SUM(I10:I5503) -> 0 | J5: =SUM(J10:J5503) -> 0 | K5: =SUM(K10:K5503) -> 0 | L5: =SUM(L10:L5503) -> 0 | M5: =SUM(M10:M5503) -> 0 | N5: =SUM(N10:N5503) -> 0 | ... AK5: =SUM(AK10:AK5503) -> 0
E6: Северо-запад | F6: ='заявки всего'!G6 -> 0 | G6: =SUMIF($E$10:$E$5503,$E$6,G10:G5503) -> 0 | H6: =SUMIF($E$10:$E$5503,$E$6,H10:H5503) -> 0 | I6: =SUMIF($E$10:$E$5503,$E$6,I10:I5503) -> 0 | J6: =SUMIF($E$10:$E$5503,$E$6,J10:J5503) -> 0 | K6: =SUMIF($E$10:$E$5503,$E$6,K10:K5503) -> 0 | L6: =SUMIF($E$10:$E$5503,$E$6,L10:L5503) -> 0 | M6: =SUMIF($E$10:$E$5503,$E$6,M10:M5503) -> 0 | N6: =SUMIF($E$10:$E$5503,$E$6,N10:N5503) -> 0 | ... AK6: =SUMIF($E$10:$E$5503,$E$6,AK10:AK5503) -> 0
E7: Восток | F7: ='заявки всего'!G7 -> 0 | G7: =SUMIF($E$10:$E$5503,$E$7,G10:G5503) -> 0 | H7: =SUMIF($E$10:$E$5503,$E$7,H10:H5503) -> 0 | I7: =SUMIF($E$10:$E$5503,$E$7,I10:I5503) -> 0 | J7: =SUMIF($E$10:$E$5503,$E$7,J10:J5503) -> 0 | K7: =SUMIF($E$10:$E$5503,$E$7,K10:K5503) -> 0 | L7: =SUMIF($E$10:$E$5503,$E$7,L10:L5503) -> 0 | M7: =SUMIF($E$10:$E$5503,$E$7,M10:M5503) -> 0 | N7: =SUMIF($E$10:$E$5503,$E$7,N10:N5503) -> 0 | ... AK7: =SUMIF($E$10:$E$5503,$E$7,AK10:AK5503) -> 0
E8: Центр | F8: ='заявки всего'!G8 -> 0 | G8: =SUMIF($E$10:$E$5503,$E$8,G10:G5503) -> 0 | H8: =SUMIF($E$10:$E$5503,$E$8,H10:H5503) -> 0 | I8: =SUMIF($E$10:$E$5503,$E$8,I10:I5503) -> 0 | J8: =SUMIF($E$10:$E$5503,$E$8,J10:J5503) -> 0 | K8: =SUMIF($E$10:$E$5503,$E$8,K10:K5503) -> 0 | L8: =SUMIF($E$10:$E$5503,$E$8,L10:L5503) -> 0 | M8: =SUMIF($E$10:$E$5503,$E$8,M10:M5503) -> 0 | N8: =SUMIF($E$10:$E$5503,$E$8,N10:N5503) -> 0 | ... AK8: =SUMIF($E$10:$E$5503,$E$8,AK10:AK5503) -> 0
E9: Юг | F9: ='заявки всего'!G9 -> 0 | G9: =SUMIF($E$10:$E$5503,$E$9,G10:G5503) -> 0 | H9: =SUMIF($E$10:$E$5503,$E$9,H10:H5503) -> 0 | I9: =SUMIF($E$10:$E$5503,$E$9,I10:I5503) -> 0 | J9: =SUMIF($E$10:$E$5503,$E$9,J10:J5503) -> 0 | K9: =SUMIF($E$10:$E$5503,$E$9,K10:K5503) -> 0 | L9: =SUMIF($E$10:$E$5503,$E$9,L10:L5503) -> 0 | M9: =SUMIF($E$10:$E$5503,$E$9,M10:M5503) -> 0 | N9: =SUMIF($E$10:$E$5503,$E$9,N10:N5503) -> 0 | ... AK9: =SUMIF($E$10:$E$5503,$E$9,AK10:AK5503) -> 0

Sheet погружено за день
B1: Погружено на день
G3: 46235
A4: Шифр | B4: Станция погрузки | C4: Дорога погрузки | D4: Клиент | E4: Дивизион | F4: Всего | G4: =G3 -> 46235 | H4: =G3+1 -> 46236 | I4: =G3+2 -> 46237 | J4: =G3+3 -> 46238 | K4: =G3+4 -> 46239 | L4: =G3+5 -> 46240 | M4: =G3+6 -> 46241 | N4: =G3+7 -> 46242 | O4: =G3+8 -> 46243 | P4: =G3+9 -> 46244 | Q4: =G3+10 -> 46245 | R4: =G3+11 -> 46246 | S4: =G3+12 -> 46247 | T4: =G3+13 -> 46248 | U4: =G3+14 -> 46249 | V4: =G3+15 -> 46250 | W4: =G3+16 -> 46251 | X4: =G3+17 -> 46252 | Y4: =G3+18 -> 46253 | Z4: =G3+19 -> 46254 | AA4: =G3+20 -> 46255 | AB4: =G3+21 -> 46256 | AC4: =G3+22 -> 46257 | AD4: =G3+23 -> 46258 | AE4: =G3+24 -> 46259 | AF4: =G3+25 -> 46260 | AG4: =G3+26 -> 46261 | AH4: =G3+27 -> 46262 | AI4: =G3+28 -> 46263 | AJ4: =G3+29 -> 46264 | AK4: =G3+30 -> 46265
E5: Всего | F5: =SUMIF(G5:AK5,"<>0") -> 0 | G5: =IF('погружено всего'!G5=0,0,'погружено всего'!G5) -> 0 | H5: =IF('погружено всего'!H5=0,0,'погружено всего'!H5-'погружено всего'!G5) -> 0 | I5: =IF('погружено всего'!I5=0,0,'погружено всего'!I5-'погружено всего'!H5) -> 0 | J5: =IF('погружено всего'!J5=0,0,'погружено всего'!J5-'погружено всего'!I5) -> 0 | K5: =IF('погружено всего'!K5=0,0,'погружено всего'!K5-'погружено всего'!J5) -> 0 | L5: =IF('погружено всего'!L5=0,0,'погружено всего'!L5-'погружено всего'!K5) -> 0 | M5: =IF('погружено всего'!M5=0,0,'погружено всего'!M5-'погружено всего'!L5) -> 0 | N5: =IF('погружено всего'!N5=0,0,'погружено всего'!N5-'погружено всего'!M5) -> 0 | O5: =IF('погружено всего'!O5=0,0,'погружено всего'!O5-'погружено всего'!N5) -> 0 | ... AK5: =IF('погружено всего'!AK5=0,0,'погружено всего'!AK5-'погружено всего'!AJ5) -> 0
E6: Северо-запад | F6: =SUMIF(G6:AK6,"<>0") -> 0 | G6: =IF('погружено всего'!G6=0,0,'погружено всего'!G6) -> 0 | H6: =IF('погружено всего'!H6=0,0,'погружено всего'!H6-'погружено всего'!G6) -> 0 | I6: =IF('погружено всего'!I6=0,0,'погружено всего'!I6-'погружено всего'!H6) -> 0 | J6: =IF('погружено всего'!J6=0,0,'погружено всего'!J6-'погружено всего'!I6) -> 0 | K6: =IF('погружено всего'!K6=0,0,'погружено всего'!K6-'погружено всего'!J6) -> 0 | L6: =IF('погружено всего'!L6=0,0,'погружено всего'!L6-'погружено всего'!K6) -> 0 | M6: =IF('погружено всего'!M6=0,0,'погружено всего'!M6-'погружено всего'!L6) -> 0 | N6: =IF('погружено всего'!N6=0,0,'погружено всего'!N6-'погружено всего'!M6) -> 0 | O6: =IF('погружено всего'!O6=0,0,'погружено всего'!O6-'погружено всего'!N6) -> 0 | ... AK6: =IF('погружено всего'!AK6=0,0,'погружено всего'!AK6-'погружено всего'!AJ6) -> 0
E7: Восток | F7: =SUMIF(G7:AK7,"<>0") -> 0 | G7: =IF('погружено всего'!G7=0,0,'погружено всего'!G7) -> 0 | H7: =IF('погружено всего'!H7=0,0,'погружено всего'!H7-'погружено всего'!G7) -> 0 | I7: =IF('погружено всего'!I7=0,0,'погружено всего'!I7-'погружено всего'!H7) -> 0 | J7: =IF('погружено всего'!J7=0,0,'погружено всего'!J7-'погружено всего'!I7) -> 0 | K7: =IF('погружено всего'!K7=0,0,'погружено всего'!K7-'погружено всего'!J7) -> 0 | L7: =IF('погружено всего'!L7=0,0,'погружено всего'!L7-'погружено всего'!K7) -> 0 | M7: =IF('погружено всего'!M7=0,0,'погружено всего'!M7-'погружено всего'!L7) -> 0 | N7: =IF('погружено всего'!N7=0,0,'погружено всего'!N7-'погружено всего'!M7) -> 0 | O7: =IF('погружено всего'!O7=0,0,'погружено всего'!O7-'погружено всего'!N7) -> 0 | ... AK7: =IF('погружено всего'!AK7=0,0,'погружено всего'!AK7-'погружено всего'!AJ7) -> 0
E8: Центр | F8: =SUMIF(G8:AK8,"<>0") -> 0 | G8: =IF('погружено всего'!G8=0,0,'погружено всего'!G8) -> 0 | H8: =IF('погружено всего'!H8=0,0,'погружено всего'!H8-'погружено всего'!G8) -> 0 | I8: =IF('погружено всего'!I8=0,0,'погружено всего'!I8-'погружено всего'!H8) -> 0 | J8: =IF('погружено всего'!J8=0,0,'погружено всего'!J8-'погружено всего'!I8) -> 0 | K8: =IF('погружено всего'!K8=0,0,'погружено всего'!K8-'погружено всего'!J8) -> 0 | L8: =IF('погружено всего'!L8=0,0,'погружено всего'!L8-'погружено всего'!K8) -> 0 | M8: =IF('погружено всего'!M8=0,0,'погружено всего'!M8-'погружено всего'!L8) -> 0 | N8: =IF('погружено всего'!N8=0,0,'погружено всего'!N8-'погружено всего'!M8) -> 0 | O8: =IF('погружено всего'!O8=0,0,'погружено всего'!O8-'погружено всего'!N8) -> 0 | ... AK8: =IF('погружено всего'!AK8=0,0,'погружено всего'!AK8-'погружено всего'!AJ8) -> 0
E9: Юг | F9: =SUMIF(G9:AK9,"<>0") -> 0 | G9: =IF('погружено всего'!G9=0,0,'погружено всего'!G9) -> 0 | H9: =IF('погружено всего'!H9=0,0,'погружено всего'!H9-'погружено всего'!G9) -> 0 | I9: =IF('погружено всего'!I9=0,0,'погружено всего'!I9-'погружено всего'!H9) -> 0 | J9: =IF('погружено всего'!J9=0,0,'погружено всего'!J9-'погружено всего'!I9) -> 0 | K9: =IF('погружено всего'!K9=0,0,'погружено всего'!K9-'погружено всего'!J9) -> 0 | L9: =IF('погружено всего'!L9=0,0,'погружено всего'!L9-'погружено всего'!K9) -> 0 | M9: =IF('погружено всего'!M9=0,0,'погружено всего'!M9-'погружено всего'!L9) -> 0 | N9: =IF('погружено всего'!N9=0,0,'погружено всего'!N9-'погружено всего'!M9) -> 0 | O9: =IF('погружено всего'!O9=0,0,'погружено всего'!O9-'погружено всего'!N9) -> 0 | ... AK9: =IF('погружено всего'!AK9=0,0,'погружено всего'!AK9-'погружено всего'!AJ9) -> 0

Sheet обеспечено
B1: Обеспечено
G2: если ячейка светло-зеленая, то заявка полностью обеспечена исполнена
G3: 46235
A4: Шифр | B4: Станция погрузки | C4: Дорога погрузки | D4: Клиент | E4: Дивизион | F4: План | G4: =G3 -> 46235 | H4: =G3+1 -> 46236 | I4: =G3+2 -> 46237 | J4: =G3+3 -> 46238 | K4: =G3+4 -> 46239 | L4: =G3+5 -> 46240 | M4: =G3+6 -> 46241 | N4: =G3+7 -> 46242 | O4: =G3+8 -> 46243 | P4: =G3+9 -> 46244 | Q4: =G3+10 -> 46245 | R4: =G3+11 -> 46246 | S4: =G3+12 -> 46247 | T4: =G3+13 -> 46248 | U4: =G3+14 -> 46249 | V4: =G3+15 -> 46250 | W4: =G3+16 -> 46251 | X4: =G3+17 -> 46252 | Y4: =G3+18 -> 46253 | Z4: =G3+19 -> 46254 | AA4: =G3+20 -> 46255 | AB4: =G3+21 -> 46256 | AC4: =G3+22 -> 46257 | AD4: =G3+23 -> 46258 | AE4: =G3+24 -> 46259 | AF4: =G3+25 -> 46260 | AG4: =G3+26 -> 46261 | AH4: =G3+27 -> 46262 | AI4: =G3+28 -> 46263 | AJ4: =G3+29 -> 46264 | AK4: =G3+30 -> 46265
E5: Всего | F5: ='заявки всего'!G5 -> 0 | G5: =SUM(G10:G5503) -> 0 | H5: =SUM(H10:H5503) -> 0 | I5: =SUM(I10:I5503) -> 0 | J5: =SUM(J10:J5503) -> 0 | K5: =SUM(K10:K5503) -> 0 | L5: =SUM(L10:L5503) -> 0 | M5: =SUM(M10:M5503) -> 0 | N5: =SUM(N10:N5503) -> 0 | ... AK5: =SUM(AK10:AK5503) -> 0
E6: Северо-запад | F6: ='заявки всего'!G6 -> 0 | G6: =SUMIF($E$10:$E$5503,$E$6,G10:G5503) -> 0 | H6: =SUMIF($E$10:$E$5503,$E$6,H10:H5503) -> 0 | I6: =SUMIF($E$10:$E$5503,$E$6,I10:I5503) -> 0 | J6: =SUMIF($E$10:$E$5503,$E$6,J10:J5503) -> 0 | K6: =SUMIF($E$10:$E$5503,$E$6,K10:K5503) -> 0 | L6: =SUMIF($E$10:$E$5503,$E$6,L10:L5503) -> 0 | M6: =SUMIF($E$10:$E$5503,$E$6,M10:M5503) -> 0 | N6: =SUMIF($E$10:$E$5503,$E$6,N10:N5503) -> 0 | ... AK6: =SUMIF($E$10:$E$5503,$E$6,AK10:AK5503) -> 0
E7: Восток | F7: ='заявки всего'!G7 -> 0 | G7: =SUMIF($E$10:$E$5503,$E$7,G10:G5503) -> 0 | H7: =SUMIF($E$10:$E$5503,$E$7,H10:H5503) -> 0 | I7: =SUMIF($E$10:$E$5503,$E$7,I10:I5503) -> 0 | J7: =SUMIF($E$10:$E$5503,$E$7,J10:J5503) -> 0 | K7: =SUMIF($E$10:$E$5503,$E$7,K10:K5503) -> 0 | L7: =SUMIF($E$10:$E$5503,$E$7,L10:L5503) -> 0 | M7: =SUMIF($E$10:$E$5503,$E$7,M10:M5503) -> 0 | N7: =SUMIF($E$10:$E$5503,$E$7,N10:N5503) -> 0 | ... AK7: =SUMIF($E$10:$E$5503,$E$7,AK10:AK5503) -> 0
E8: Центр | F8: ='заявки всего'!G8 -> 0 | G8: =SUMIF($E$10:$E$5503,$E$8,G10:G5503) -> 0 | H8: =SUMIF($E$10:$E$5503,$E$8,H10:H5503) -> 0 | I8: =SUMIF($E$10:$E$5503,$E$8,I10:I5503) -> 0 | J8: =SUMIF($E$10:$E$5503,$E$8,J10:J5503) -> 0 | K8: =SUMIF($E$10:$E$5503,$E$8,K10:K5503) -> 0 | L8: =SUMIF($E$10:$E$5503,$E$8,L10:L5503) -> 0 | M8: =SUMIF($E$10:$E$5503,$E$8,M10:M5503) -> 0 | N8: =SUMIF($E$10:$E$5503,$E$8,N10:N5503) -> 0 | ... AK8: =SUMIF($E$10:$E$5503,$E$8,AK10:AK5503) -> 0
E9: Юг | F9: ='заявки всего'!G9 -> 0 | G9: =SUMIF($E$10:$E$5503,$E$9,G10:G5503) -> 0 | H9: =SUMIF($E$10:$E$5503,$E$9,H10:H5503) -> 0 | I9: =SUMIF($E$10:$E$5503,$E$9,I10:I5503) -> 0 | J9: =SUMIF($E$10:$E$5503,$E$9,J10:J5503) -> 0 | K9: =SUMIF($E$10:$E$5503,$E$9,K10:K5503) -> 0 | L9: =SUMIF($E$10:$E$5503,$E$9,L10:L5503) -> 0 | M9: =SUMIF($E$10:$E$5503,$E$9,M10:M5503) -> 0 | N9: =SUMIF($E$10:$E$5503,$E$9,N10:N5503) -> 0 | ... AK9: =SUMIF($E$10:$E$5503,$E$9,AK10:AK5503) -> 0

Sheet наличие
B1: Ежесуточное наличие
G3: 46235
A4: Шифр | B4: Станция погрузки | C4: Дорога погрузки | D4: Клиент | E4: Дивизион | F4: Норма | G4: 1 | H4: 2 | I4: 3 | J4: 4 | K4: 5 | L4: 6 | M4: 7 | N4: 8 | O4: 9 | P4: 10 | Q4: 11 | R4: 12 | S4: 13 | T4: 14 | U4: 15 | V4: 16 | W4: 17 | X4: 18 | Y4: 19 | Z4: 20 | AA4: 21 | AB4: 22 | AC4: 23 | AD4: 24 | AE4: 25 | AF4: 26 | AG4: 27 | AH4: 28 | AI4: 29 | AJ4: 30 | AK4: 31
E5: Всего | F5: ='заявки всего'!G5/31*5 -> 0 | G5: =SUM(G10:G5503) -> 0 | H5: =SUM(H10:H5503) -> 0 | I5: =SUM(I10:I5503) -> 0 | J5: =SUM(J10:J5503) -> 0 | K5: =SUM(K10:K5503) -> 0 | L5: =SUM(L10:L5503) -> 0 | M5: =SUM(M10:M5503) -> 0 | N5: =SUM(N10:N5503) -> 0 | ... AK5: =SUM(AK10:AK5503) -> 0
E6: Северо-запад | F6: ='заявки всего'!G6/31*5 -> 0 | G6: =SUMIF($E$10:$E$5503,$E$6,G10:G5503) -> 0 | H6: =SUMIF($E$10:$E$5503,$E$6,H10:H5503) -> 0 | I6: =SUMIF($E$10:$E$5503,$E$6,I10:I5503) -> 0 | J6: =SUMIF($E$10:$E$5503,$E$6,J10:J5503) -> 0 | K6: =SUMIF($E$10:$E$5503,$E$6,K10:K5503) -> 0 | L6: =SUMIF($E$10:$E$5503,$E$6,L10:L5503) -> 0 | M6: =SUMIF($E$10:$E$5503,$E$6,M10:M5503) -> 0 | N6: =SUMIF($E$10:$E$5503,$E$6,N10:N5503) -> 0 | ... AK6: =SUMIF($E$10:$E$5503,$E$6,AK10:AK5503) -> 0
E7: Восток | F7: ='заявки всего'!G7/31*5 -> 0 | G7: =SUMIF($E$10:$E$5503,$E$7,G10:G5503) -> 0 | H7: =SUMIF($E$10:$E$5503,$E$7,H10:H5503) -> 0 | I7: =SUMIF($E$10:$E$5503,$E$7,I10:I5503) -> 0 | J7: =SUMIF($E$10:$E$5503,$E$7,J10:J5503) -> 0 | K7: =SUMIF($E$10:$E$5503,$E$7,K10:K5503) -> 0 | L7: =SUMIF($E$10:$E$5503,$E$7,L10:L5503) -> 0 | M7: =SUMIF($E$10:$E$5503,$E$7,M10:M5503) -> 0 | N7: =SUMIF($E$10:$E$5503,$E$7,N10:N5503) -> 0 | ... AK7: =SUMIF($E$10:$E$5503,$E$7,AK10:AK5503) -> 0
E8: Центр | F8: ='заявки всего'!G8/31*5 -> 0 | G8: =SUMIF($E$10:$E$5503,$E$8,G10:G5503) -> 0 | H8: =SUMIF($E$10:$E$5503,$E$8,H10:H5503) -> 0 | I8: =SUMIF($E$10:$E$5503,$E$8,I10:I5503) -> 0 | J8: =SUMIF($E$10:$E$5503,$E$8,J10:J5503) -> 0 | K8: =SUMIF($E$10:$E$5503,$E$8,K10:K5503) -> 0 | L8: =SUMIF($E$10:$E$5503,$E$8,L10:L5503) -> 0 | M8: =SUMIF($E$10:$E$5503,$E$8,M10:M5503) -> 0 | N8: =SUMIF($E$10:$E$5503,$E$8,N10:N5503) -> 0 | ... AK8: =SUMIF($E$10:$E$5503,$E$8,AK10:AK5503) -> 0
E9: Юг | F9: ='заявки всего'!G9/31*5 -> 0 | G9: =SUMIF($E$10:$E$5503,$E$9,G10:G5503) -> 0 | H9: =SUMIF($E$10:$E$5503,$E$9,H10:H5503) -> 0 | I9: =SUMIF($E$10:$E$5503,$E$9,I10:I5503) -> 0 | J9: =SUMIF($E$10:$E$5503,$E$9,J10:J5503) -> 0 | K9: =SUMIF($E$10:$E$5503,$E$9,K10:K5503) -> 0 | L9: =SUMIF($E$10:$E$5503,$E$9,L10:L5503) -> 0 | M9: =SUMIF($E$10:$E$5503,$E$9,M10:M5503) -> 0 | N9: =SUMIF($E$10:$E$5503,$E$9,N10:N5503) -> 0 | ... AK9: =SUMIF($E$10:$E$5503,$E$9,AK10:AK5503) -> 0
A10: КрытыеОАО "Монди СЛПК"КОЙТЫ | B10: =IF(LEN('заявки всего'!B10)=0,"",'заявки всего'!B10) | C10: =IF(LEN('заявки всего'!C10)=0,"",'заявки всего'!C10) | D10: =IF(LEN('заявки всего'!D10)=0,"",'заявки всего'!D10) | E10: =IF(LEN('заявки всего'!E10)=0,"",'заявки всего'!E10) | F10: =IF(обеспечено!F10=0,"",ROUNDUP(обеспечено!F10/31*5,0)) | G10: =IF(обеспечено!G10-'погружено всего'!G10=0,"",обеспечено!G10-'погружено всего'!G10) | H10: =IF(обеспечено!H10-'погружено всего'!H10=0,"",обеспечено!H10-'погружено всего'!H10) | I10: =IF(обеспечено!I10-'погружено всего'!I10=0,"",обеспечено!I10-'погружено всего'!I10) | J10: =IF(обеспечено!J10-'погружено всего'!J10=0,"",обеспечено!J10-'погружено всего'!J10) | K10: =IF(обеспечено!K10-'погружено всего'!K10=0,"",обеспечено!K10-'погружено всего'!K10) | L10: =IF(обеспечено!L10-'погружено всего'!L10=0,"",обеспечено!L10-'погружено всего'!L10) | M10: =IF(обеспечено!M10-'погружено всего'!M10=0,"",обеспечено!M10-'погружено всего'!M10) | N10: =IF(обеспечено!N10-'погружено всего'!N10=0,"",обеспечено!N10-'погружено всего'!N10) | ... AK10: =IF(обеспечено!AK10-'погружено всего'!AK10=0,"",обеспечено!AK10-'погружено всего'!AK10)
A11: КрытыеЗАО "Интернешнл Пейпер"СВЕТОГОРСК | B11: =IF(LEN('заявки всего'!B11)=0,"",'заявки всего'!B11) | C11: =IF(LEN('заявки всего'!C11)=0,"",'заявки всего'!C11) | D11: =IF(LEN('заявки всего'!D11)=0,"",'заявки всего'!D11) | E11: =IF(LEN('заявки всего'!E11)=0,"",'заявки всего'!E11) | F11: =IF(обеспечено!F11=0,"",ROUNDUP(обеспечено!F11/31*5,0)) | G11: =IF(обеспечено!G11-'погружено всего'!G11=0,"",обеспечено!G11-'погружено всего'!G11) | H11: =IF(обеспечено!H11-'погружено всего'!H11=0,"",обеспечено!H11-'погружено всего'!H11) | I11: =IF(обеспечено!I11-'погружено всего'!I11=0,"",обеспечено!I11-'погружено всего'!I11) | J11: =IF(обеспечено!J11-'погружено всего'!J11=0,"",обеспечено!J11-'погружено всего'!J11) | K11: =IF(обеспечено!K11-'погружено всего'!K11=0,"",обеспечено!K11-'погружено всего'!K11) | L11: =IF(обеспечено!L11-'погружено всего'!L11=0,"",обеспечено!L11-'погружено всего'!L11) | M11: =IF(обеспечено!M11-'погружено всего'!M11=0,"",обеспечено!M11-'погружено всего'!M11) | N11: =IF(обеспечено!N11-'погружено всего'!N11=0,"",обеспечено!N11-'погружено всего'!N11) | ... AK11: =IF(обеспечено!AK11-'погружено всего'!AK11=0,"",обеспечено!AK11-'погружено всего'!AK11)
A12: КрытыеОАО "Нижнекамскнефтехим" ("НКНХ")БИКЛЯНЬ | B12: =IF(LEN('заявки всего'!B12)=0,"",'заявки всего'!B12) | C12: =IF(LEN('заявки всего'!C12)=0,"",'заявки всего'!C12) | D12: =IF(LEN('заявки всего'!D12)=0,"",'заявки всего'!D12) | E12: =IF(LEN('заявки всего'!E12)=0,"",'заявки всего'!E12) | F12: =IF(обеспечено!F12=0,"",ROUNDUP(обеспечено!F12/31*5,0)) | G12: =IF(обеспечено!G12-'погружено всего'!G12=0,"",обеспечено!G12-'погружено всего'!G12) | H12: =IF(обеспечено!H12-'погружено всего'!H12=0,"",обеспечено!H12-'погружено всего'!H12) | I12: =IF(обеспечено!I12-'погружено всего'!I12=0,"",обеспечено!I12-'погружено всего'!I12) | J12: =IF(обеспечено!J12-'погружено всего'!J12=0,"",обеспечено!J12-'погружено всего'!J12) | K12: =IF(обеспечено!K12-'погружено всего'!K12=0,"",обеспечено!K12-'погружено всего'!K12) | L12: =IF(обеспечено!L12-'погружено всего'!L12=0,"",обеспечено!L12-'погружено всего'!L12) | M12: =IF(обеспечено!M12-'погружено всего'!M12=0,"",обеспечено!M12-'погружено всего'!M12) | N12: =IF(обеспечено!N12-'погружено всего'!N12=0,"",обеспечено!N12-'погружено всего'!N12) | ... AK12: =IF(обеспечено!AK12-'погружено всего'!AK12=0,"",обеспечено!AK12-'погружено всего'!AK12)
A13: КрытыеКучуксульфат ОАОНОВОБЛАГОВЕЩЕНКА | B13: =IF(LEN('заявки всего'!B13)=0,"",'заявки всего'!B13) | C13: =IF(LEN('заявки всего'!C13)=0,"",'заявки всего'!C13) | D13: =IF(LEN('заявки всего'!D13)=0,"",'заявки всего'!D13) | E13: =IF(LEN('заявки всего'!E13)=0,"",'заявки всего'!E13) | F13: =IF(обеспечено!F13=0,"",ROUNDUP(обеспечено!F13/31*5,0)) | G13: =IF(обеспечено!G13-'погружено всего'!G13=0,"",обеспечено!G13-'погружено всего'!G13) | H13: =IF(обеспечено!H13-'погружено всего'!H13=0,"",обеспечено!H13-'погружено всего'!H13) | I13: =IF(обеспечено!I13-'погружено всего'!I13=0,"",обеспечено!I13-'погружено всего'!I13) | J13: =IF(обеспечено!J13-'погружено всего'!J13=0,"",обеспечено!J13-'погружено всего'!J13) | K13: =IF(обеспечено!K13-'погружено всего'!K13=0,"",обеспечено!K13-'погружено всего'!K13) | L13: =IF(обеспечено!L13-'погружено всего'!L13=0,"",обеспечено!L13-'погружено всего'!L13) | M13: =IF(обеспечено!M13-'погружено всего'!M13=0,"",обеспечено!M13-'погружено всего'!M13) | N13: =IF(обеспечено!N13-'погружено всего'!N13=0,"",обеспечено!N13-'погружено всего'!N13) | ... AK13: =IF(обеспечено!AK13-'погружено всего'!AK13=0,"",обеспечено!AK13-'погружено всего'!AK13)
A14: КрытыеООО "Жешартский ЛПК"МЕЖЕГ | B14: =IF(LEN('заявки всего'!B14)=0,"",'заявки всего'!B14) | C14: =IF(LEN('заявки всего'!C14)=0,"",'заявки всего'!C14) | D14: =IF(LEN('заявки всего'!D14)=0,"",'заявки всего'!D14) | E14: =IF(LEN('заявки всего'!E14)=0,"",'заявки всего'!E14) | F14: =IF(обеспечено!F14=0,"",ROUNDUP(обеспечено!F14/31*5,0)) | G14: =IF(обеспечено!G14-'погружено всего'!G14=0,"",обеспечено!G14-'погружено всего'!G14) | H14: =IF(обеспечено!H14-'погружено всего'!H14=0,"",обеспечено!H14-'погружено всего'!H14) | I14: =IF(обеспечено!I14-'погружено всего'!I14=0,"",обеспечено!I14-'погружено всего'!I14) | J14: =IF(обеспечено!J14-'погружено всего'!J14=0,"",обеспечено!J14-'погружено всего'!J14) | K14: =IF(обеспечено!K14-'погружено всего'!K14=0,"",обеспечено!K14-'погружено всего'!K14) | L14: =IF(обеспечено!L14-'погружено всего'!L14=0,"",обеспечено!L14-'погружено всего'!L14) | M14: =IF(обеспечено!M14-'погружено всего'!M14=0,"",обеспечено!M14-'погружено всего'!M14) | N14: =IF(обеспечено!N14-'погружено всего'!N14=0,"",обеспечено!N14-'погружено всего'!N14) | ... AK14: =IF(обеспечено!AK14-'погружено всего'!AK14=0,"",обеспечено!AK14-'погружено всего'!AK14)
A15: КрытыеООО "Керама Марацци"ЛУЖКИ-ОРЛОВСКИЕ | B15: =IF(LEN('заявки всего'!B15)=0,"",'заявки всего'!B15) | C15: =IF(LEN('заявки всего'!C15)=0,"",'заявки всего'!C15) | D15: =IF(LEN('заявки всего'!D15)=0,"",'заявки всего'!D15) | E15: =IF(LEN('заявки всего'!E15)=0,"",'заявки всего'!E15) | F15: =IF(обеспечено!F15=0,"",ROUNDUP(обеспечено!F15/31*5,0)) | G15: =IF(обеспечено!G15-'погружено всего'!G15=0,"",обеспечено!G15-'погружено всего'!G15) | H15: =IF(обеспечено!H15-'погружено всего'!H15=0,"",обеспечено!H15-'погружено всего'!H15) | I15: =IF(обеспечено!I15-'погружено всего'!I15=0,"",обеспечено!I15-'погружено всего'!I15) | J15: =IF(обеспечено!J15-'погружено всего'!J15=0,"",обеспечено!J15-'погружено всего'!J15) | K15: =IF(обеспечено!K15-'погружено всего'!K15=0,"",обеспечено!K15-'погружено всего'!K15) | L15: =IF(обеспечено!L15-'погружено всего'!L15=0,"",обеспечено!L15-'погружено всего'!L15) | M15: =IF(обеспечено!M15-'погружено всего'!M15=0,"",обеспечено!M15-'погружено всего'!M15) | N15: =IF(обеспечено!N15-'погружено всего'!N15=0,"",обеспечено!N15-'погружено всего'!N15) | ... AK15: =IF(обеспечено!AK15-'погружено всего'!AK15=0,"",обеспечено!AK15-'погружено всего'!AK15)
A16: КрытыеООО "Группа "Магнезит""РЕЧНАЯ | B16: =IF(LEN('заявки всего'!B16)=0,"",'заявки всего'!B16) | C16: =IF(LEN('заявки всего'!C16)=0,"",'заявки всего'!C16) | D16: =IF(LEN('заявки всего'!D16)=0,"",'заявки всего'!D16) | E16: =IF(LEN('заявки всего'!E16)=0,"",'заявки всего'!E16) | F16: =IF(обеспечено!F16=0,"",ROUNDUP(обеспечено!F16/31*5,0)) | G16: =IF(обеспечено!G16-'погружено всего'!G16=0,"",обеспечено!G16-'погружено всего'!G16) | H16: =IF(обеспечено!H16-'погружено всего'!H16=0,"",обеспечено!H16-'погружено всего'!H16) | I16: =IF(обеспечено!I16-'погружено всего'!I16=0,"",обеспечено!I16-'погружено всего'!I16) | J16: =IF(обеспечено!J16-'погружено всего'!J16=0,"",обеспечено!J16-'погружено всего'!J16) | K16: =IF(обеспечено!K16-'погружено всего'!K16=0,"",обеспечено!K16-'погружено всего'!K16) | L16: =IF(обеспечено!L16-'погружено всего'!L16=0,"",обеспечено!L16-'погружено всего'!L16) | M16: =IF(обеспечено!M16-'погружено всего'!M16=0,"",обеспечено!M16-'погружено всего'!M16) | N16: =IF(обеспечено!N16-'погружено всего'!N16=0,"",обеспечено!N16-'погружено всего'!N16) | ... AK16: =IF(обеспечено!AK16-'погружено всего'!AK16=0,"",обеспечено!AK16-'погружено всего'!AK16)
A17: КрытыеООО "Кнауф Гипс Байкал"ЗАЛАРИ | B17: =IF(LEN('заявки всего'!B17)=0,"",'заявки всего'!B17) | C17: =IF(LEN('заявки всего'!C17)=0,"",'заявки всего'!C17) | D17: =IF(LEN('заявки всего'!D17)=0,"",'заявки всего'!D17) | E17: =IF(LEN('заявки всего'!E17)=0,"",'заявки всего'!E17) | F17: =IF(обеспечено!F17=0,"",ROUNDUP(обеспечено!F17/31*5,0)) | G17: =IF(обеспечено!G17-'погружено всего'!G17=0,"",обеспечено!G17-'погружено всего'!G17) | H17: =IF(обеспечено!H17-'погружено всего'!H17=0,"",обеспечено!H17-'погружено всего'!H17) | I17: =IF(обеспечено!I17-'погружено всего'!I17=0,"",обеспечено!I17-'погружено всего'!I17) | J17: =IF(обеспечено!J17-'погружено всего'!J17=0,"",обеспечено!J17-'погружено всего'!J17) | K17: =IF(обеспечено!K17-'погружено всего'!K17=0,"",обеспечено!K17-'погружено всего'!K17) | L17: =IF(обеспечено!L17-'погружено всего'!L17=0,"",обеспечено!L17-'погружено всего'!L17) | M17: =IF(обеспечено!M17-'погружено всего'!M17=0,"",обеспечено!M17-'погружено всего'!M17) | N17: =IF(обеспечено!N17-'погружено всего'!N17=0,"",обеспечено!N17-'погружено всего'!N17) | ... AK17: =IF(обеспечено!AK17-'погружено всего'!AK17=0,"",обеспечено!AK17-'погружено всего'!AK17)
A18: КрытыеТОО "Евросиб Казахстан"САРАХС (ЭКСП.) | B18: =IF(LEN('заявки всего'!B18)=0,"",'заявки всего'!B18) | C18: =IF(LEN('заявки всего'!C18)=0,"",'заявки всего'!C18) | D18: =IF(LEN('заявки всего'!D18)=0,"",'заявки всего'!D18) | E18: =IF(LEN('заявки всего'!E18)=0,"",'заявки всего'!E18) | F18: =IF(обеспечено!F18=0,"",ROUNDUP(обеспечено!F18/31*5,0)) | G18: =IF(обеспечено!G18-'погружено всего'!G18=0,"",обеспечено!G18-'погружено всего'!G18) | H18: =IF(обеспечено!H18-'погружено всего'!H18=0,"",обеспечено!H18-'погружено всего'!H18) | I18: =IF(обеспечено!I18-'погружено всего'!I18=0,"",обеспечено!I18-'погружено всего'!I18) | J18: =IF(обеспечено!J18-'погружено всего'!J18=0,"",обеспечено!J18-'погружено всего'!J18) | K18: =IF(обеспечено!K18-'погружено всего'!K18=0,"",обеспечено!K18-'погружено всего'!K18) | L18: =IF(обеспечено!L18-'погружено всего'!L18=0,"",обеспечено!L18-'погружено всего'!L18) | M18: =IF(обеспечено!M18-'погружено всего'!M18=0,"",обеспечено!M18-'погружено всего'!M18) | N18: =IF(обеспечено!N18-'погружено всего'!N18=0,"",обеспечено!N18-'погружено всего'!N18) | ... AK18: =IF(обеспечено!AK18-'погружено всего'!AK18=0,"",обеспечено!AK18-'погружено всего'!AK18)
A19: КрытыеООО "Сен-Гобен Строительная Продукция Рус"ВОРСМА | B19: =IF(LEN('заявки всего'!B19)=0,"",'заявки всего'!B19) | C19: =IF(LEN('заявки всего'!C19)=0,"",'заявки всего'!C19) | D19: =IF(LEN('заявки всего'!D19)=0,"",'заявки всего'!D19) | E19: =IF(LEN('заявки всего'!E19)=0,"",'заявки всего'!E19) | F19: =IF(обеспечено!F19=0,"",ROUNDUP(обеспечено!F19/31*5,0)) | G19: =IF(обеспечено!G19-'погружено всего'!G19=0,"",обеспечено!G19-'погружено всего'!G19) | H19: =IF(обеспечено!H19-'погружено всего'!H19=0,"",обеспечено!H19-'погружено всего'!H19) | I19: =IF(обеспечено!I19-'погружено всего'!I19=0,"",обеспечено!I19-'погружено всего'!I19) | J19: =IF(обеспечено!J19-'погружено всего'!J19=0,"",обеспечено!J19-'погружено всего'!J19) | K19: =IF(обеспечено!K19-'погружено всего'!K19=0,"",обеспечено!K19-'погружено всего'!K19) | L19: =IF(обеспечено!L19-'погружено всего'!L19=0,"",обеспечено!L19-'погружено всего'!L19) | M19: =IF(обеспечено!M19-'погружено всего'!M19=0,"",обеспечено!M19-'погружено всего'!M19) | N19: =IF(обеспечено!N19-'погружено всего'!N19=0,"",обеспечено!N19-'погружено всего'!N19) | ... AK19: =IF(обеспечено!AK19-'погружено всего'!AK19=0,"",обеспечено!AK19-'погружено всего'!AK19)
A20: КрытыеFOSCOTE TRADING AND INVESTMENTS LIMITEDКОСЯКОВКА | B20: =IF(LEN('заявки всего'!B20)=0,"",'заявки всего'!B20) | C20: =IF(LEN('заявки всего'!C20)=0,"",'заявки всего'!C20) | D20: =IF(LEN('заявки всего'!D20)=0,"",'заявки всего'!D20) | E20: =IF(LEN('заявки всего'!E20)=0,"",'заявки всего'!E20) | F20: =IF(обеспечено!F20=0,"",ROUNDUP(обеспечено!F20/31*5,0)) | G20: =IF(обеспечено!G20-'погружено всего'!G20=0,"",обеспечено!G20-'погружено всего'!G20) | H20: =IF(обеспечено!H20-'погружено всего'!H20=0,"",обеспечено!H20-'погружено всего'!H20) | I20: =IF(обеспечено!I20-'погружено всего'!I20=0,"",обеспечено!I20-'погружено всего'!I20) | J20: =IF(обеспечено!J20-'погружено всего'!J20=0,"",обеспечено!J20-'погружено всего'!J20) | K20: =IF(обеспечено!K20-'погружено всего'!K20=0,"",обеспечено!K20-'погружено всего'!K20) | L20: =IF(обеспечено!L20-'погружено всего'!L20=0,"",обеспечено!L20-'погружено всего'!L20) | M20: =IF(обеспечено!M20-'погружено всего'!M20=0,"",обеспечено!M20-'погружено всего'!M20) | N20: =IF(обеспечено!N20-'погружено всего'!N20=0,"",обеспечено!N20-'погружено всего'!N20) | ... AK20: =IF(обеспечено!AK20-'погружено всего'!AK20=0,"",обеспечено!AK20-'погружено всего'!AK20)
A21: КрытыеОбщество с ограниченной ответственностью "АМИЛКО"МИЛЛЕРОВО | B21: =IF(LEN('заявки всего'!B21)=0,"",'заявки всего'!B21) | C21: =IF(LEN('заявки всего'!C21)=0,"",'заявки всего'!C21) | D21: =IF(LEN('заявки всего'!D21)=0,"",'заявки всего'!D21) | E21: =IF(LEN('заявки всего'!E21)=0,"",'заявки всего'!E21) | F21: =IF(обеспечено!F21=0,"",ROUNDUP(обеспечено!F21/31*5,0)) | G21: =IF(обеспечено!G21-'погружено всего'!G21=0,"",обеспечено!G21-'погружено всего'!G21) | H21: =IF(обеспечено!H21-'погружено всего'!H21=0,"",обеспечено!H21-'погружено всего'!H21) | I21: =IF(обеспечено!I21-'погружено всего'!I21=0,"",обеспечено!I21-'погружено всего'!I21) | J21: =IF(обеспечено!J21-'погружено всего'!J21=0,"",обеспечено!J21-'погружено всего'!J21) | K21: =IF(обеспечено!K21-'погружено всего'!K21=0,"",обеспечено!K21-'погружено всего'!K21) | L21: =IF(обеспечено!L21-'погружено всего'!L21=0,"",обеспечено!L21-'погружено всего'!L21) | M21: =IF(обеспечено!M21-'погружено всего'!M21=0,"",обеспечено!M21-'погружено всего'!M21) | N21: =IF(обеспечено!N21-'погружено всего'!N21=0,"",обеспечено!N21-'погружено всего'!N21) | ... AK21: =IF(обеспечено!AK21-'погружено всего'!AK21=0,"",обеспечено!AK21-'погружено всего'!AK21)
... A475: КрытыеООО "ТЛК Новотранс"БИЙСК | B475: =IF(LEN('заявки всего'!B475)=0,"",'заявки всего'!B475) | C475: =IF(LEN('заявки всего'!C475)=0,"",'заявки всего'!C475) | D475: =IF(LEN('заявки всего'!D475)=0,"",'заявки всего'!D475) | E475: =IF(LEN('заявки всего'!E475)=0,"",'заявки всего'!E475) | F475: =IF(обеспечено!F475=0,"",ROUNDUP(обеспечено!F475/31*5,0)) | G475: =IF(обеспечено!G475-'погружено всего'!G475=0,"",обеспечено!G475-'погружено всего'!G475) | H475: =IF(обеспечено!H475-'погружено всего'!H475=0,"",обеспечено!H475-'погружено всего'!H475) | I475: =IF(обеспечено!I475-'погружено всего'!I475=0,"",обеспечено!I475-'погружено всего'!I475) | J475: =IF(обеспечено!J475-'погружено всего'!J475=0,"",обеспечено!J475-'погружено всего'!J475) | K475: =IF(обеспечено!K475-'погружено всего'!K475=0,"",обеспечено!K475-'погружено всего'!K475) | L475: =IF(обеспечено!L475-'погружено всего'!L475=0,"",обеспечено!L475-'погружено всего'!L475) | M475: =IF(обеспечено!M475-'погружено всего'!M475=0,"",обеспечено!M475-'погружено всего'!M475) | N475: =IF(обеспечено!N475-'погружено всего'!N475=0,"",обеспечено!N475-'погружено всего'!N475) | ... AK475: =IF(обеспечено!AK475-'погружено всего'!AK475=0,"",обеспечено!AK475-'погружено всего'!AK475)
B476: =IF(LEN('заявки всего'!B476)=0,"",'заявки всего'!B476) | C476: =IF(LEN('заявки всего'!C476)=0,"",'заявки всего'!C476) | D476: =IF(LEN('заявки всего'!D476)=0,"",'заявки всего'!D476) | E476: =IF(LEN('заявки всего'!E476)=0,"",'заявки всего'!E476) | F476: =IF(обеспечено!F476=0,"",ROUNDUP(обеспечено!F476/31*5,0)) | G476: =IF(обеспечено!G476-'погружено всего'!G476=0,"",обеспечено!G476-'погружено всего'!G476) | H476: =IF(обеспечено!H476-'погружено всего'!H476=0,"",обеспечено!H476-'погружено всего'!H476) | I476: =IF(обеспечено!I476-'погружено всего'!I476=0,"",обеспечено!I476-'погружено всего'!I476) | J476: =IF(обеспечено!J476-'погружено всего'!J476=0,"",обеспечено!J476-'погружено всего'!J476) | K476: =IF(обеспечено!K476-'погружено всего'!K476=0,"",обеспечено!K476-'погружено всего'!K476) | L476: =IF(обеспечено!L476-'погружено всего'!L476=0,"",обеспечено!L476-'погружено всего'!L476) | M476: =IF(обеспечено!M476-'погружено всего'!M476=0,"",обеспечено!M476-'погружено всего'!M476) | N476: =IF(обеспечено!N476-'погружено всего'!N476=0,"",обеспечено!N476-'погружено всего'!N476) | ... AK476: =IF(обеспечено!AK476-'погружено всего'!AK476=0,"",обеспечено!AK476-'погружено всего'!AK476)
B477: =IF(LEN('заявки всего'!B477)=0,"",'заявки всего'!B477) | C477: =IF(LEN('заявки всего'!C477)=0,"",'заявки всего'!C477) | D477: =IF(LEN('заявки всего'!D477)=0,"",'заявки всего'!D477) | E477: =IF(LEN('заявки всего'!E477)=0,"",'заявки всего'!E477) | F477: =IF(обеспечено!F477=0,"",ROUNDUP(обеспечено!F477/31*5,0)) | G477: =IF(обеспечено!G477-'погружено всего'!G477=0,"",обеспечено!G477-'погружено всего'!G477) | H477: =IF(обеспечено!H477-'погружено всего'!H477=0,"",обеспечено!H477-'погружено всего'!H477) | I477: =IF(обеспечено!I477-'погружено всего'!I477=0,"",обеспечено!I477-'погружено всего'!I477) | J477: =IF(обеспечено!J477-'погружено всего'!J477=0,"",обеспечено!J477-'погружено всего'!J477) | K477: =IF(обеспечено!K477-'погружено всего'!K477=0,"",обеспечено!K477-'погружено всего'!K477) | L477: =IF(обеспечено!L477-'погружено всего'!L477=0,"",обеспечено!L477-'погружено всего'!L477) | M477: =IF(обеспечено!M477-'погружено всего'!M477=0,"",обеспечено!M477-'погружено всего'!M477) | N477: =IF(обеспечено!N477-'погружено всего'!N477=0,"",обеспечено!N477-'погружено всего'!N477) | ... AK477: =IF(обеспечено!AK477-'погружено всего'!AK477=0,"",обеспечено!AK477-'погружено всего'!AK477)
B478: =IF(LEN('заявки всего'!B478)=0,"",'заявки всего'!B478) | C478: =IF(LEN('заявки всего'!C478)=0,"",'заявки всего'!C478) | D478: =IF(LEN('заявки всего'!D478)=0,"",'заявки всего'!D478) | E478: =IF(LEN('заявки всего'!E478)=0,"",'заявки всего'!E478) | F478: =IF(обеспечено!F478=0,"",ROUNDUP(обеспечено!F478/31*5,0)) | G478: =IF(обеспечено!G478-'погружено всего'!G478=0,"",обеспечено!G478-'погружено всего'!G478) | H478: =IF(обеспечено!H478-'погружено всего'!H478=0,"",обеспечено!H478-'погружено всего'!H478) | I478: =IF(обеспечено!I478-'погружено всего'!I478=0,"",обеспечено!I478-'погружено всего'!I478) | J478: =IF(обеспечено!J478-'погружено всего'!J478=0,"",обеспечено!J478-'погружено всего'!J478) | K478: =IF(обеспечено!K478-'погружено всего'!K478=0,"",обеспечено!K478-'погружено всего'!K478) | L478: =IF(обеспечено!L478-'погружено всего'!L478=0,"",обеспечено!L478-'погружено всего'!L478) | M478: =IF(обеспечено!M478-'погружено всего'!M478=0,"",обеспечено!M478-'погружено всего'!M478) | N478: =IF(обеспечено!N478-'погружено всего'!N478=0,"",обеспечено!N478-'погружено всего'!N478) | ... AK478: =IF(обеспечено!AK478-'погружено всего'!AK478=0,"",обеспечено!AK478-'погружено всего'!AK478)
B479: =IF(LEN('заявки всего'!B479)=0,"",'заявки всего'!B479) | C479: =IF(LEN('заявки всего'!C479)=0,"",'заявки всего'!C479) | D479: =IF(LEN('заявки всего'!D479)=0,"",'заявки всего'!D479) | E479: =IF(LEN('заявки всего'!E479)=0,"",'заявки всего'!E479) | F479: =IF(обеспечено!F479=0,"",ROUNDUP(обеспечено!F479/31*5,0)) | G479: =IF(обеспечено!G479-'погружено всего'!G479=0,"",обеспечено!G479-'погружено всего'!G479) | H479: =IF(обеспечено!H479-'погружено всего'!H479=0,"",обеспечено!H479-'погружено всего'!H479) | I479: =IF(обеспечено!I479-'погружено всего'!I479=0,"",обеспечено!I479-'погружено всего'!I479) | J479: =IF(обеспечено!J479-'погружено всего'!J479=0,"",обеспечено!J479-'погружено всего'!J479) | K479: =IF(обеспечено!K479-'погружено всего'!K479=0,"",обеспечено!K479-'погружено всего'!K479) | L479: =IF(обеспечено!L479-'погружено всего'!L479=0,"",обеспечено!L479-'погружено всего'!L479) | M479: =IF(обеспечено!M479-'погружено всего'!M479=0,"",обеспечено!M479-'погружено всего'!M479) | N479: =IF(обеспечено!N479-'погружено всего'!N479=0,"",обеспечено!N479-'погружено всего'!N479) | ... AK479: =IF(обеспечено!AK479-'погружено всего'!AK479=0,"",обеспечено!AK479-'погружено всего'!AK479)
B480: =IF(LEN('заявки всего'!B480)=0,"",'заявки всего'!B480) | C480: =IF(LEN('заявки всего'!C480)=0,"",'заявки всего'!C480) | D480: =IF(LEN('заявки всего'!D480)=0,"",'заявки всего'!D480) | E480: =IF(LEN('заявки всего'!E480)=0,"",'заявки всего'!E480) | F480: =IF(обеспечено!F480=0,"",ROUNDUP(обеспечено!F480/31*5,0)) | G480: =IF(обеспечено!G480-'погружено всего'!G480=0,"",обеспечено!G480-'погружено всего'!G480) | H480: =IF(обеспечено!H480-'погружено всего'!H480=0,"",обеспечено!H480-'погружено всего'!H480) | I480: =IF(обеспечено!I480-'погружено всего'!I480=0,"",обеспечено!I480-'погружено всего'!I480) | J480: =IF(обеспечено!J480-'погружено всего'!J480=0,"",обеспечено!J480-'погружено всего'!J480) | K480: =IF(обеспечено!K480-'погружено всего'!K480=0,"",обеспечено!K480-'погружено всего'!K480) | L480: =IF(обеспечено!L480-'погружено всего'!L480=0,"",обеспечено!L480-'погружено всего'!L480) | M480: =IF(обеспечено!M480-'погружено всего'!M480=0,"",обеспечено!M480-'погружено всего'!M480) | N480: =IF(обеспечено!N480-'погружено всего'!N480=0,"",обеспечено!N480-'погружено всего'!N480) | ... AK480: =IF(обеспечено!AK480-'погружено всего'!AK480=0,"",обеспечено!AK480-'погружено всего'!AK480)
B481: =IF(LEN('заявки всего'!B481)=0,"",'заявки всего'!B481) | C481: =IF(LEN('заявки всего'!C481)=0,"",'заявки всего'!C481) | D481: =IF(LEN('заявки всего'!D481)=0,"",'заявки всего'!D481) | E481: =IF(LEN('заявки всего'!E481)=0,"",'заявки всего'!E481) | F481: =IF(обеспечено!F481=0,"",ROUNDUP(обеспечено!F481/31*5,0)) | G481: =IF(обеспечено!G481-'погружено всего'!G481=0,"",обеспечено!G481-'погружено всего'!G481) | H481: =IF(обеспечено!H481-'погружено всего'!H481=0,"",обеспечено!H481-'погружено всего'!H481) | I481: =IF(обеспечено!I481-'погружено всего'!I481=0,"",обеспечено!I481-'погружено всего'!I481) | J481: =IF(обеспечено!J481-'погружено всего'!J481=0,"",обеспечено!J481-'погружено всего'!J481) | K481: =IF(обеспечено!K481-'погружено всего'!K481=0,"",обеспечено!K481-'погружено всего'!K481) | L481: =IF(обеспечено!L481-'погружено всего'!L481=0,"",обеспечено!L481-'погружено всего'!L481) | M481: =IF(обеспечено!M481-'погружено всего'!M481=0,"",обеспечено!M481-'погружено всего'!M481) | N481: =IF(обеспечено!N481-'погружено всего'!N481=0,"",обеспечено!N481-'погружено всего'!N481) | ... AK481: =IF(обеспечено!AK481-'погружено всего'!AK481=0,"",обеспечено!AK481-'погружено всего'!AK481)
B482: =IF(LEN('заявки всего'!B482)=0,"",'заявки всего'!B482) | C482: =IF(LEN('заявки всего'!C482)=0,"",'заявки всего'!C482) | D482: =IF(LEN('заявки всего'!D482)=0,"",'заявки всего'!D482) | E482: =IF(LEN('заявки всего'!E482)=0,"",'заявки всего'!E482) | F482: =IF(обеспечено!F482=0,"",ROUNDUP(обеспечено!F482/31*5,0)) | G482: =IF(обеспечено!G482-'погружено всего'!G482=0,"",обеспечено!G482-'погружено всего'!G482) | H482: =IF(обеспечено!H482-'погружено всего'!H482=0,"",обеспечено!H482-'погружено всего'!H482) | I482: =IF(обеспечено!I482-'погружено всего'!I482=0,"",обеспечено!I482-'погружено всего'!I482) | J482: =IF(обеспечено!J482-'погружено всего'!J482=0,"",обеспечено!J482-'погружено всего'!J482) | K482: =IF(обеспечено!K482-'погружено всего'!K482=0,"",обеспечено!K482-'погружено всего'!K482) | L482: =IF(обеспечено!L482-'погружено всего'!L482=0,"",обеспечено!L482-'погружено всего'!L482) | M482: =IF(обеспечено!M482-'погружено всего'!M482=0,"",обеспечено!M482-'погружено всего'!M482) | N482: =IF(обеспечено!N482-'погружено всего'!N482=0,"",обеспечено!N482-'погружено всего'!N482) | ... AK482: =IF(обеспечено!AK482-'погружено всего'!AK482=0,"",обеспечено!AK482-'погружено всего'!AK482)
B483: =IF(LEN('заявки всего'!B483)=0,"",'заявки всего'!B483) | C483: =IF(LEN('заявки всего'!C483)=0,"",'заявки всего'!C483) | D483: =IF(LEN('заявки всего'!D483)=0,"",'заявки всего'!D483) | E483: =IF(LEN('заявки всего'!E483)=0,"",'заявки всего'!E483) | F483: =IF(обеспечено!F483=0,"",ROUNDUP(обеспечено!F483/31*5,0)) | G483: =IF(обеспечено!G483-'погружено всего'!G483=0,"",обеспечено!G483-'погружено всего'!G483) | H483: =IF(обеспечено!H483-'погружено всего'!H483=0,"",обеспечено!H483-'погружено всего'!H483) | I483: =IF(обеспечено!I483-'погружено всего'!I483=0,"",обеспечено!I483-'погружено всего'!I483) | J483: =IF(обеспечено!J483-'погружено всего'!J483=0,"",обеспечено!J483-'погружено всего'!J483) | K483: =IF(обеспечено!K483-'погружено всего'!K483=0,"",обеспечено!K483-'погружено всего'!K483) | L483: =IF(обеспечено!L483-'погружено всего'!L483=0,"",обеспечено!L483-'погружено всего'!L483) | M483: =IF(обеспечено!M483-'погружено всего'!M483=0,"",обеспечено!M483-'погружено всего'!M483) | N483: =IF(обеспечено!N483-'погружено всего'!N483=0,"",обеспечено!N483-'погружено всего'!N483) | ... AK483: =IF(обеспечено!AK483-'погружено всего'!AK483=0,"",обеспечено!AK483-'погружено всего'!AK483)
B484: =IF(LEN('заявки всего'!B484)=0,"",'заявки всего'!B484) | C484: =IF(LEN('заявки всего'!C484)=0,"",'заявки всего'!C484) | D484: =IF(LEN('заявки всего'!D484)=0,"",'заявки всего'!D484) | E484: =IF(LEN('заявки всего'!E484)=0,"",'заявки всего'!E484) | F484: =IF(обеспечено!F484=0,"",ROUNDUP(обеспечено!F484/31*5,0)) | G484: =IF(обеспечено!G484-'погружено всего'!G484=0,"",обеспечено!G484-'погружено всего'!G484) | H484: =IF(обеспечено!H484-'погружено всего'!H484=0,"",обеспечено!H484-'погружено всего'!H484) | I484: =IF(обеспечено!I484-'погружено всего'!I484=0,"",обеспечено!I484-'погружено всего'!I484) | J484: =IF(обеспечено!J484-'погружено всего'!J484=0,"",обеспечено!J484-'погружено всего'!J484) | K484: =IF(обеспечено!K484-'погружено всего'!K484=0,"",обеспечено!K484-'погружено всего'!K484) | L484: =IF(обеспечено!L484-'погружено всего'!L484=0,"",обеспечено!L484-'погружено всего'!L484) | M484: =IF(обеспечено!M484-'погружено всего'!M484=0,"",обеспечено!M484-'погружено всего'!M484) | N484: =IF(обеспечено!N484-'погружено всего'!N484=0,"",обеспечено!N484-'погружено всего'!N484) | ... AK484: =IF(обеспечено!AK484-'погружено всего'!AK484=0,"",обеспечено!AK484-'погружено всего'!AK484)
B485: =IF(LEN('заявки всего'!B485)=0,"",'заявки всего'!B485) | C485: =IF(LEN('заявки всего'!C485)=0,"",'заявки всего'!C485) | D485: =IF(LEN('заявки всего'!D485)=0,"",'заявки всего'!D485) | E485: =IF(LEN('заявки всего'!E485)=0,"",'заявки всего'!E485) | F485: =IF(обеспечено!F485=0,"",ROUNDUP(обеспечено!F485/31*5,0)) | G485: =IF(обеспечено!G485-'погружено всего'!G485=0,"",обеспечено!G485-'погружено всего'!G485) | H485: =IF(обеспечено!H485-'погружено всего'!H485=0,"",обеспечено!H485-'погружено всего'!H485) | I485: =IF(обеспечено!I485-'погружено всего'!I485=0,"",обеспечено!I485-'погружено всего'!I485) | J485: =IF(обеспечено!J485-'погружено всего'!J485=0,"",обеспечено!J485-'погружено всего'!J485) | K485: =IF(обеспечено!K485-'погружено всего'!K485=0,"",обеспечено!K485-'погружено всего'!K485) | L485: =IF(обеспечено!L485-'погружено всего'!L485=0,"",обеспечено!L485-'погружено всего'!L485) | M485: =IF(обеспечено!M485-'погружено всего'!M485=0,"",обеспечено!M485-'погружено всего'!M485) | N485: =IF(обеспечено!N485-'погружено всего'!N485=0,"",обеспечено!N485-'погружено всего'!N485) | ... AK485: =IF(обеспечено!AK485-'погружено всего'!AK485=0,"",обеспечено!AK485-'погружено всего'!AK485)
B486: =IF(LEN('заявки всего'!B486)=0,"",'заявки всего'!B486) | C486: =IF(LEN('заявки всего'!C486)=0,"",'заявки всего'!C486) | D486: =IF(LEN('заявки всего'!D486)=0,"",'заявки всего'!D486) | E486: =IF(LEN('заявки всего'!E486)=0,"",'заявки всего'!E486) | F486: =IF(обеспечено!F486=0,"",ROUNDUP(обеспечено!F486/31*5,0)) | G486: =IF(обеспечено!G486-'погружено всего'!G486=0,"",обеспечено!G486-'погружено всего'!G486) | H486: =IF(обеспечено!H486-'погружено всего'!H486=0,"",обеспечено!H486-'погружено всего'!H486) | I486: =IF(обеспечено!I486-'погружено всего'!I486=0,"",обеспечено!I486-'погружено всего'!I486) | J486: =IF(обеспечено!J486-'погружено всего'!J486=0,"",обеспечено!J486-'погружено всего'!J486) | K486: =IF(обеспечено!K486-'погружено всего'!K486=0,"",обеспечено!K486-'погружено всего'!K486) | L486: =IF(обеспечено!L486-'погружено всего'!L486=0,"",обеспечено!L486-'погружено всего'!L486) | M486: =IF(обеспечено!M486-'погружено всего'!M486=0,"",обеспечено!M486-'погружено всего'!M486) | N486: =IF(обеспечено!N486-'погружено всего'!N486=0,"",обеспечено!N486-'погружено всего'!N486) | ... AK486: =IF(обеспечено!AK486-'погружено всего'!AK486=0,"",обеспечено!AK486-'погружено всего'!AK486)
B487: =IF(LEN('заявки всего'!B487)=0,"",'заявки всего'!B487) | C487: =IF(LEN('заявки всего'!C487)=0,"",'заявки всего'!C487) | D487: =IF(LEN('заявки всего'!D487)=0,"",'заявки всего'!D487) | E487: =IF(LEN('заявки всего'!E487)=0,"",'заявки всего'!E487) | F487: =IF(обеспечено!F487=0,"",ROUNDUP(обеспечено!F487/31*5,0)) | G487: =IF(обеспечено!G487-'погружено всего'!G487=0,"",обеспечено!G487-'погружено всего'!G487) | H487: =IF(обеспечено!H487-'погружено всего'!H487=0,"",обеспечено!H487-'погружено всего'!H487) | I487: =IF(обеспечено!I487-'погружено всего'!I487=0,"",обеспечено!I487-'погружено всего'!I487) | J487: =IF(обеспечено!J487-'погружено всего'!J487=0,"",обеспечено!J487-'погружено всего'!J487) | K487: =IF(обеспечено!K487-'погружено всего'!K487=0,"",обеспечено!K487-'погружено всего'!K487) | L487: =IF(обеспечено!L487-'погружено всего'!L487=0,"",обеспечено!L487-'погружено всего'!L487) | M487: =IF(обеспечено!M487-'погружено всего'!M487=0,"",обеспечено!M487-'погружено всего'!M487) | N487: =IF(обеспечено!N487-'погружено всего'!N487=0,"",обеспечено!N487-'погружено всего'!N487) | ... AK487: =IF(обеспечено!AK487-'погружено всего'!AK487=0,"",обеспечено!AK487-'погружено всего'!AK487)
... B1000: =IF(LEN('заявки всего'!B1000)=0,"",'заявки всего'!B1000) | C1000: =IF(LEN('заявки всего'!C1000)=0,"",'заявки всего'!C1000) | D1000: =IF(LEN('заявки всего'!D1000)=0,"",'заявки всего'!D1000) | E1000: =IF(LEN('заявки всего'!E1000)=0,"",'заявки всего'!E1000) | F1000: =IF(обеспечено!F1000=0,"",ROUNDUP(обеспечено!F1000/31*5,0)) | G1000: =IF(обеспечено!G1000-'погружено всего'!G1000=0,"",обеспечено!G1000-'погружено всего'!G1000) | H1000: =IF(обеспечено!H1000-'погружено всего'!H1000=0,"",обеспечено!H1000-'погружено всего'!H1000) | I1000: =IF(обеспечено!I1000-'погружено всего'!I1000=0,"",обеспечено!I1000-'погружено всего'!I1000) | J1000: =IF(обеспечено!J1000-'погружено всего'!J1000=0,"",обеспечено!J1000-'погружено всего'!J1000) | K1000: =IF(обеспечено!K1000-'погружено всего'!K1000=0,"",обеспечено!K1000-'погружено всего'!K1000) | L1000: =IF(обеспечено!L1000-'погружено всего'!L1000=0,"",обеспечено!L1000-'погружено всего'!L1000) | M1000: =IF(обеспечено!M1000-'погружено всего'!M1000=0,"",обеспечено!M1000-'погружено всего'!M1000) | N1000: =IF(обеспечено!N1000-'погружено всего'!N1000=0,"",обеспечено!N1000-'погружено всего'!N1000) | ... AK1000: =IF(обеспечено!AK1000-'погружено всего'!AK1000=0,"",обеспечено!AK1000-'погружено всего'!AK1000)

Sheet размечено всего
B1: Размечено всего
G3: 46235
A4: Шифр | B4: Станция погрузки | C4: Дорога погрузки | D4: Клиент | E4: Дивизион | F4: Всего | G4: =G3 -> 46235 | H4: =G3+1 -> 46236 | I4: =G3+2 -> 46237 | J4: =G3+3 -> 46238 | K4: =G3+4 -> 46239 | L4: =G3+5 -> 46240 | M4: =G3+6 -> 46241 | N4: =G3+7 -> 46242 | O4: =G3+8 -> 46243 | P4: =G3+9 -> 46244 | Q4: =G3+10 -> 46245 | R4: =G3+11 -> 46246 | S4: =G3+12 -> 46247 | T4: =G3+13 -> 46248 | U4: =G3+14 -> 46249 | V4: =G3+15 -> 46250 | W4: =G3+16 -> 46251 | X4: =G3+17 -> 46252 | Y4: =G3+18 -> 46253 | Z4: =G3+19 -> 46254 | AA4: =G3+20 -> 46255 | AB4: =G3+21 -> 46256 | AC4: =G3+22 -> 46257 | AD4: =G3+23 -> 46258 | AE4: =G3+24 -> 46259 | AF4: =G3+25 -> 46260 | AG4: =G3+26 -> 46261 | AH4: =G3+27 -> 46262 | AI4: =G3+28 -> 46263 | AJ4: =G3+29 -> 46264 | AK4: =G3+30 -> 46265
E5: Всего | F5: =AVERAGEIF(G5:AK5,"<>0") -> #DIV/0! | G5: =SUM(G10:G5503) -> 0 | H5: =SUM(H10:H5503) -> 0 | I5: =SUM(I10:I5503) -> 0 | J5: =SUM(J10:J5503) -> 0 | K5: =SUM(K10:K5503) -> 0 | L5: =SUM(L10:L5503) -> 0 | M5: =SUM(M10:M5503) -> 0 | N5: =SUM(N10:N5503) -> 0 | ... AK5: =SUM(AK10:AK5503) -> 0
E6: Северо-запад | F6: =AVERAGEIF(G6:AK6,"<>0") -> #DIV/0! | G6: =SUMIF($E$10:$E$5503,$E$6,G10:G5503) -> 0 | H6: =SUMIF($E$10:$E$5503,$E$6,H10:H5503) -> 0 | I6: =SUMIF($E$10:$E$5503,$E$6,I10:I5503) -> 0 | J6: =SUMIF($E$10:$E$5503,$E$6,J10:J5503) -> 0 | K6: =SUMIF($E$10:$E$5503,$E$6,K10:K5503) -> 0 | L6: =SUMIF($E$10:$E$5503,$E$6,L10:L5503) -> 0 | M6: =SUMIF($E$10:$E$5503,$E$6,M10:M5503) -> 0 | N6: =SUMIF($E$10:$E$5503,$E$6,N10:N5503) -> 0 | ... AK6: =SUMIF($E$10:$E$5503,$E$6,AK10:AK5503) -> 0
E7: Восток | F7: =AVERAGEIF(G7:AK7,"<>0") -> #DIV/0! | G7: =SUMIF($E$10:$E$5503,$E$7,G10:G5503) -> 0 | H7: =SUMIF($E$10:$E$5503,$E$7,H10:H5503) -> 0 | I7: =SUMIF($E$10:$E$5503,$E$7,I10:I5503) -> 0 | J7: =SUMIF($E$10:$E$5503,$E$7,J10:J5503) -> 0 | K7: =SUMIF($E$10:$E$5503,$E$7,K10:K5503) -> 0 | L7: =SUMIF($E$10:$E$5503,$E$7,L10:L5503) -> 0 | M7: =SUMIF($E$10:$E$5503,$E$7,M10:M5503) -> 0 | N7: =SUMIF($E$10:$E$5503,$E$7,N10:N5503) -> 0 | ... AK7: =SUMIF($E$10:$E$5503,$E$7,AK10:AK5503) -> 0
E8: Центр | F8: =AVERAGEIF(G8:AK8,"<>0") -> #DIV/0! | G8: =SUMIF($E$10:$E$5503,$E$8,G10:G5503) -> 0 | H8: =SUMIF($E$10:$E$5503,$E$8,H10:H5503) -> 0 | I8: =SUMIF($E$10:$E$5503,$E$8,I10:I5503) -> 0 | J8: =SUMIF($E$10:$E$5503,$E$8,J10:J5503) -> 0 | K8: =SUMIF($E$10:$E$5503,$E$8,K10:K5503) -> 0 | L8: =SUMIF($E$10:$E$5503,$E$8,L10:L5503) -> 0 | M8: =SUMIF($E$10:$E$5503,$E$8,M10:M5503) -> 0 | N8: =SUMIF($E$10:$E$5503,$E$8,N10:N5503) -> 0 | ... AK8: =SUMIF($E$10:$E$5503,$E$8,AK10:AK5503) -> 0
E9: Юг | F9: =AVERAGEIF(G9:AK9,"<>0") -> #DIV/0! | G9: =SUMIF($E$10:$E$5503,$E$9,G10:G5503) -> 0 | H9: =SUMIF($E$10:$E$5503,$E$9,H10:H5503) -> 0 | I9: =SUMIF($E$10:$E$5503,$E$9,I10:I5503) -> 0 | J9: =SUMIF($E$10:$E$5503,$E$9,J10:J5503) -> 0 | K9: =SUMIF($E$10:$E$5503,$E$9,K10:K5503) -> 0 | L9: =SUMIF($E$10:$E$5503,$E$9,L10:L5503) -> 0 | M9: =SUMIF($E$10:$E$5503,$E$9,M10:M5503) -> 0 | N9: =SUMIF($E$10:$E$5503,$E$9,N10:N5503) -> 0 | ... AK9: =SUMIF($E$10:$E$5503,$E$9,AK10:AK5503) -> 0

Sheet размечено за день
B1: Размечено за день
G3: 46235
A4: Шифр | B4: Станция погрузки | C4: Дорога погрузки | D4: Клиент | E4: Дивизион | F4: Всего | G4: =G3 -> 46235 | H4: =G3+1 -> 46236 | I4: =G3+2 -> 46237 | J4: =G3+3 -> 46238 | K4: =G3+4 -> 46239 | L4: =G3+5 -> 46240 | M4: =G3+6 -> 46241 | N4: =G3+7 -> 46242 | O4: =G3+8 -> 46243 | P4: =G3+9 -> 46244 | Q4: =G3+10 -> 46245 | R4: =G3+11 -> 46246 | S4: =G3+12 -> 46247 | T4: =G3+13 -> 46248 | U4: =G3+14 -> 46249 | V4: =G3+15 -> 46250 | W4: =G3+16 -> 46251 | X4: =G3+17 -> 46252 | Y4: =G3+18 -> 46253 | Z4: =G3+19 -> 46254 | AA4: =G3+20 -> 46255 | AB4: =G3+21 -> 46256 | AC4: =G3+22 -> 46257 | AD4: =G3+23 -> 46258 | AE4: =G3+24 -> 46259 | AF4: =G3+25 -> 46260 | AG4: =G3+26 -> 46261 | AH4: =G3+27 -> 46262 | AI4: =G3+28 -> 46263 | AJ4: =G3+29 -> 46264 | AK4: =G3+30 -> 46265
E5: Всего | F5: =SUMIF(G5:AK5,"<>0") -> 0 | G5: =SUM(G10:G5503) -> 0 | H5: =SUM(H10:H5503) -> 0 | I5: =SUM(I10:I5503) -> 0 | J5: =SUM(J10:J5503) -> 0 | K5: =SUM(K10:K5503) -> 0 | L5: =SUM(L10:L5503) -> 0 | M5: =SUM(M10:M5503) -> 0 | N5: =SUM(N10:N5503) -> 0 | ... AK5: =SUM(AK10:AK5503) -> 0
E6: Северо-запад | F6: =SUMIF(G6:AK6,"<>0") -> 0 | G6: =SUMIF($E$10:$E$5503,$E$6,G10:G5503) -> 0 | H6: =SUMIF($E$10:$E$5503,$E$6,H10:H5503) -> 0 | I6: =SUMIF($E$10:$E$5503,$E$6,I10:I5503) -> 0 | J6: =SUMIF($E$10:$E$5503,$E$6,J10:J5503) -> 0 | K6: =SUMIF($E$10:$E$5503,$E$6,K10:K5503) -> 0 | L6: =SUMIF($E$10:$E$5503,$E$6,L10:L5503) -> 0 | M6: =SUMIF($E$10:$E$5503,$E$6,M10:M5503) -> 0 | N6: =SUMIF($E$10:$E$5503,$E$6,N10:N5503) -> 0 | ... AK6: =SUMIF($E$10:$E$5503,$E$6,AK10:AK5503) -> 0
E7: Восток | F7: =SUMIF(G7:AK7,"<>0") -> 0 | G7: =SUMIF($E$10:$E$5503,$E$7,G10:G5503) -> 0 | H7: =SUMIF($E$10:$E$5503,$E$7,H10:H5503) -> 0 | I7: =SUMIF($E$10:$E$5503,$E$7,I10:I5503) -> 0 | J7: =SUMIF($E$10:$E$5503,$E$7,J10:J5503) -> 0 | K7: =SUMIF($E$10:$E$5503,$E$7,K10:K5503) -> 0 | L7: =SUMIF($E$10:$E$5503,$E$7,L10:L5503) -> 0 | M7: =SUMIF($E$10:$E$5503,$E$7,M10:M5503) -> 0 | N7: =SUMIF($E$10:$E$5503,$E$7,N10:N5503) -> 0 | ... AK7: =SUMIF($E$10:$E$5503,$E$7,AK10:AK5503) -> 0
E8: Центр | F8: =SUMIF(G8:AK8,"<>0") -> 0 | G8: =SUMIF($E$10:$E$5503,$E$8,G10:G5503) -> 0 | H8: =SUMIF($E$10:$E$5503,$E$8,H10:H5503) -> 0 | I8: =SUMIF($E$10:$E$5503,$E$8,I10:I5503) -> 0 | J8: =SUMIF($E$10:$E$5503,$E$8,J10:J5503) -> 0 | K8: =SUMIF($E$10:$E$5503,$E$8,K10:K5503) -> 0 | L8: =SUMIF($E$10:$E$5503,$E$8,L10:L5503) -> 0 | M8: =SUMIF($E$10:$E$5503,$E$8,M10:M5503) -> 0 | N8: =SUMIF($E$10:$E$5503,$E$8,N10:N5503) -> 0 | ... AK8: =SUMIF($E$10:$E$5503,$E$8,AK10:AK5503) -> 0
E9: Юг | F9: =SUMIF(G9:AK9,"<>0") -> 0 | G9: =SUMIF($E$10:$E$5503,$E$9,G10:G5503) -> 0 | H9: =SUMIF($E$10:$E$5503,$E$9,H10:H5503) -> 0 | I9: =SUMIF($E$10:$E$5503,$E$9,I10:I5503) -> 0 | J9: =SUMIF($E$10:$E$5503,$E$9,J10:J5503) -> 0 | K9: =SUMIF($E$10:$E$5503,$E$9,K10:K5503) -> 0 | L9: =SUMIF($E$10:$E$5503,$E$9,L10:L5503) -> 0 | M9: =SUMIF($E$10:$E$5503,$E$9,M10:M5503) -> 0 | N9: =SUMIF($E$10:$E$5503,$E$9,N10:N5503) -> 0 | ... AK9: =SUMIF($E$10:$E$5503,$E$9,AK10:AK5503) -> 0

Sheet стоплист,  стопотгрузка
B1: Стоп-Погрузки и стоп-подсылы
G2: ячейки посветлее (2) - стоп-отгрузка. Ячейки потемнее (1) - стоп-лист. В итоговой части таблицы числитель - стоп-лист, знаменатель -стоп-отгрузка
G3: 46235
A4: Шифр | B4: Станция погрузки | C4: Дорога погрузки | D4: Клиент | E4: Дивизион | F4: Всего | G4: =G3 -> 46235 | H4: =G3+1 -> 46236 | I4: =G3+2 -> 46237 | J4: =G3+3 -> 46238 | K4: =G3+4 -> 46239 | L4: =G3+5 -> 46240 | M4: =G3+6 -> 46241 | N4: =G3+7 -> 46242 | O4: =G3+8 -> 46243 | P4: =G3+9 -> 46244 | Q4: =G3+10 -> 46245 | R4: =G3+11 -> 46246 | S4: =G3+12 -> 46247 | T4: =G3+13 -> 46248 | U4: =G3+14 -> 46249 | V4: =G3+15 -> 46250 | W4: =G3+16 -> 46251 | X4: =G3+17 -> 46252 | Y4: =G3+18 -> 46253 | Z4: =G3+19 -> 46254 | AA4: =G3+20 -> 46255 | AB4: =G3+21 -> 46256 | AC4: =G3+22 -> 46257 | AD4: =G3+23 -> 46258 | AE4: =G3+24 -> 46259 | AF4: =G3+25 -> 46260 | AG4: =G3+26 -> 46261 | AH4: =G3+27 -> 46262 | AI4: =G3+28 -> 46263 | AJ4: =G3+29 -> 46264 | AK4: =G3+30 -> 46265
E5: Всего | F5: =AVERAGEIF(G5:AK5,">0") -> #DIV/0! | G5: =IF(SUM(G9:G2499)=0,"",COUNTIF(G10:G2500,2)+COUNTIF(G10:G2500,1)) | H5: =IF(SUM(H9:H2499)=0,"",COUNTIF(H10:H2500,2)+COUNTIF(H10:H2500,1)) | I5: =IF(SUM(I9:I2499)=0,"",COUNTIF(I10:I2500,2)+COUNTIF(I10:I2500,1)) | J5: =IF(SUM(J9:J2499)=0,"",COUNTIF(J10:J2500,2)+COUNTIF(J10:J2500,1)) | K5: =IF(SUM(K9:K2499)=0,"",COUNTIF(K10:K2500,2)+COUNTIF(K10:K2500,1)) | L5: =IF(SUM(L9:L2499)=0,"",COUNTIF(L10:L2500,2)+COUNTIF(L10:L2500,1)) | M5: =IF(SUM(M9:M2499)=0,"",COUNTIF(M10:M2500,2)+COUNTIF(M10:M2500,1)) | N5: =IF(SUM(N9:N2499)=0,"",COUNTIF(N10:N2500,2)+COUNTIF(N10:N2500,1)) | ... AK5: =IF(SUM(AK9:AK2499)=0,"",COUNTIF(AK10:AK2500,2)+COUNTIF(AK10:AK2500,1))
